Workbook

Sheet FOGLIO RECAP
B3: PROGRAMMA DI ALLENAMENTO
B8: NOME | I8: ETÀ
B9: RUOLO | I9: PESO
B11: OBIETTIVI
B14: LIVELLO ATTUALE - Dettaglio
B15: CAPAC. ANAEROBICA | D15: =AVERAGE(TEST!E7:E10) -> 80
B16: RESISTENZA | D16: =AVERAGE(TEST!E3:E4) -> 75
B17: FORZA PB | D17: =AVERAGE(TEST!E13:E17) -> 84.92
B18: FORZA PA | D18: =AVERAGE(TEST!E20:E22) -> 84.777778
B19: VELOCITÀ | D19: =AVERAGE(TEST!E25:E26) -> 80.357143
B20: FORZA ESPLOSIVA | D20: =AVERAGE(TEST!E29:E31) -> 85.837438
B21: FASCIA | D21: =AVERAGE(TEST!E34:E36) -> 91.666667
B22: TECNICA | D22: =AVERAGE(TEST!E39:E46) -> 83.152778
B36: LIVELLO ATTUALE - Generale
B37: RESISTENZA | D37: =AVERAGE(TEST!E7:E10,TEST!E7:E10) -> 80
B38: FORZA | D38: =AVERAGE(TEST!E3:E4,TEST!E20:E22) -> 80.866667
B39: VELOCITÀ | D39: =AVERAGE(TEST!E13:E17) -> 84.92
B40: TECNICA | D40: =AVERAGE(TEST!E20:E22) -> 84.777778
B41: PREVENZIONE | D41: =AVERAGE(TEST!E25:E26,TEST!E8:E10) -> 76.142857

Sheet SETTIMANA 1
A1: SETTIMANA | B1: 1 | D1: FOCUS ALLENAMENTO | F1: SETTIMANA | G1: 1 | I1: FOCUS ALLENAMENTO | K1: SETTIMANA | L1: 1 | N1: FOCUS ALLENAMENTO | P1: SETTIMANA | Q1: 1 | S1: FOCUS ALLENAMENTO | U1: SETTIMANA | V1: 1 | X1: FOCUS ALLENAMENTO
A2: GIORNO | B2: 1 | F2: GIORNO | G2: 2 | K2: GIORNO | L2: 3 | P2: GIORNO | Q2: 4 | U2: GIORNO | V2: 5
A3: RISCALDAMENTO | B3: REPS/TEMPO | C3: RECUPERO | D3: DESCRIZIONE/NOTE | E3: LINK | F3: RISCALDAMENTO | G3: REPS/TEMPO | H3: RECUPERO | I3: DESCRIZIONE/NOTE | J3: LINK | K3: RISCALDAMENTO | L3: REPS/TEMPO | M3: RECUPERO | N3: DESCRIZIONE/NOTE | O3: LINK | P3: RISCALDAMENTO | Q3: REPS/TEMPO | R3: RECUPERO | S3: DESCRIZIONE/NOTE | T3: LINK | U3: RISCALDAMENTO | V3: REPS/TEMPO | W3: RECUPERO | X3: DESCRIZIONE/NOTE | Y3: LINK
A4: Towel Curls | D4: =IF($A4="","",VLOOKUP(A4,'DB ESERCIZI'!$B$2:$K$83,9,FALSE)) -> esegui una retrazione del piede utilizzando un asciugamano | E4: =IF($A4="","",HYPERLINK(VLOOKUP(A4,'DB ESERCIZI'!$B$2:$K$83,10,FALSE))) -> https://youtube.com/shorts/qW8YXLmdke0 | F4: Towel Curls | I4: =IF($A4="","",VLOOKUP(F4,'DB ESERCIZI'!$B$2:$K$83,9,FALSE)) -> esegui una retrazione del piede utilizzando un asciugamano | J4: =IF($A4="","",HYPERLINK(VLOOKUP(F4,'DB ESERCIZI'!$B$2:$K$83,10,FALSE))) -> https://youtube.com/shorts/qW8YXLmdke0 | K4: Towel Curls | N4: =IF($A4="","",VLOOKUP(K4,'DB ESERCIZI'!$B$2:$K$83,9,FALSE)) -> esegui una retrazione del piede utilizzando un asciugamano | O4: =IF($A4="","",HYPERLINK(VLOOKUP(K4,'DB ESERCIZI'!$B$2:$K$83,10,FALSE))) -> https://youtube.com/shorts/qW8YXLmdke0 | P4: Towel Curls | S4: =IF($A4="","",VLOOKUP(P4,'DB ESERCIZI'!$B$2:$K$83,9,FALSE)) -> esegui una retrazione del piede utilizzando un asciugamano | T4: =IF($A4="","",HYPERLINK(VLOOKUP(P4,'DB ESERCIZI'!$B$2:$K$83,10,FALSE))) -> https://youtube.com/shorts/qW8YXLmdke0 | U4: Towel Curls | X4: =IF($A4="","",VLOOKUP(U4,'DB ESERCIZI'!$B$2:$K$83,9,FALSE)) -> esegui una retrazione del piede utilizzando un asciugamano | Y4: =IF($A4="","",HYPERLINK(VLOOKUP(U4,'DB ESERCIZI'!$B$2:$K$83,10,FALSE))) -> https://youtube.com/shorts/qW8YXLmdke0
A5: Towel Curls | D5: =IF(A5="","",VLOOKUP(A5,'DB ESERCIZI'!$B$2:$K$83,9,FALSE)) -> esegui una retrazione del piede utilizzando un asciugamano | E5: =IF($A5="","",HYPERLINK(VLOOKUP(A5,'DB ESERCIZI'!$B$2:$K$83,10,FALSE))) -> https://youtube.com/shorts/qW8YXLmdke0 | F5: Towel Curls | I5: =IF(F5="","",VLOOKUP(F5,'DB ESERCIZI'!$B$2:$K$83,9,FALSE)) -> esegui una retrazione del piede utilizzando un asciugamano | J5: =IF($A5="","",HYPERLINK(VLOOKUP(F5,'DB ESERCIZI'!$B$2:$K$83,10,FALSE))) -> https://youtube.com/shorts/qW8YXLmdke0 | K5: Towel Curls | N5: =IF(K5="","",VLOOKUP(K5,'DB ESERCIZI'!$B$2:$K$83,9,FALSE)) -> esegui una retrazione del piede utilizzando un asciugamano | O5: =IF($A5="","",HYPERLINK(VLOOKUP(K5,'DB ESERCIZI'!$B$2:$K$83,10,FALSE))) -> https://youtube.com/shorts/qW8YXLmdke0 | P5: Towel Curls | S5: =IF(P5="","",VLOOKUP(P5,'DB ESERCIZI'!$B$2:$K$83,9,FALSE)) -> esegui una retrazione del piede utilizzando un asciugamano | T5: =IF($A5="","",HYPERLINK(VLOOKUP(P5,'DB ESERCIZI'!$B$2:$K$83,10,FALSE))) -> https://youtube.com/shorts/qW8YXLmdke0 | U5: Towel Curls | X5: =IF(U5="","",VLOOKUP(U5,'DB ESERCIZI'!$B$2:$K$83,9,FALSE)) -> esegui una retrazione del piede utilizzando un asciugamano | Y5: =IF($A5="","",HYPERLINK(VLOOKUP(U5,'DB ESERCIZI'!$B$2:$K$83,10,FALSE))) -> https://youtube.com/shorts/qW8YXLmdke0
D6: =IF(A6="","",VLOOKUP(A6,'DB ESERCIZI'!$B$2:$K$83,9,FALSE)) | E6: =IF($A6="","",HYPERLINK(VLOOKUP(A6,'DB ESERCIZI'!$B$2:$K$83,10,FALSE))) | I6: =IF(F6="","",VLOOKUP(F6,'DB ESERCIZI'!$B$2:$K$83,9,FALSE)) | J6: =IF($A6="","",HYPERLINK(VLOOKUP(F6,'DB ESERCIZI'!$B$2:$K$83,10,FALSE))) | N6: =IF(K6="","",VLOOKUP(K6,'DB ESERCIZI'!$B$2:$K$83,9,FALSE)) | O6: =IF($A6="","",HYPERLINK(VLOOKUP(K6,'DB ESERCIZI'!$B$2:$K$83,10,FALSE))) | S6: =IF(P6="","",VLOOKUP(P6,'DB ESERCIZI'!$B$2:$K$83,9,FALSE)) | T6: =IF($A6="","",HYPERLINK(VLOOKUP(P6,'DB ESERCIZI'!$B$2:$K$83,10,FALSE))) | X6: =IF(U6="","",VLOOKUP(U6,'DB ESERCIZI'!$B$2:$K$83,9,FALSE)) | Y6: =IF($A6="","",HYPERLINK(VLOOKUP(U6,'DB ESERCIZI'!$B$2:$K$83,10,FALSE)))
D7: =IF(A7="","",VLOOKUP(A7,'DB ESERCIZI'!$B$2:$K$83,9,FALSE)) | E7: =IF($A7="","",HYPERLINK(VLOOKUP(A7,'DB ESERCIZI'!$B$2:$K$83,10,FALSE))) | I7: =IF(F7="","",VLOOKUP(F7,'DB ESERCIZI'!$B$2:$K$83,9,FALSE)) | J7: =IF($A7="","",HYPERLINK(VLOOKUP(F7,'DB ESERCIZI'!$B$2:$K$83,10,FALSE))) | N7: =IF(K7="","",VLOOKUP(K7,'DB ESERCIZI'!$B$2:$K$83,9,FALSE)) | O7: =IF($A7="","",HYPERLINK(VLOOKUP(K7,'DB ESERCIZI'!$B$2:$K$83,10,FALSE))) | S7: =IF(P7="","",VLOOKUP(P7,'DB ESERCIZI'!$B$2:$K$83,9,FALSE)) | T7: =IF($A7="","",HYPERLINK(VLOOKUP(P7,'DB ESERCIZI'!$B$2:$K$83,10,FALSE))) | X7: =IF(U7="","",VLOOKUP(U7,'DB ESERCIZI'!$B$2:$K$83,9,FALSE)) | Y7: =IF($A7="","",HYPERLINK(VLOOKUP(U7,'DB ESERCIZI'!$B$2:$K$83,10,FALSE)))
A8: ALLENAMENTO | B8: REPS/TEMPO | C8: RECUPERO | D8: DESCRIZIONE/NOTE | E8: LINK | F8: ALLENAMENTO | G8: REPS/TEMPO | H8: RECUPERO | I8: DESCRIZIONE/NOTE | J8: LINK | K8: ALLENAMENTO | L8: REPS/TEMPO | M8: RECUPERO | N8: DESCRIZIONE/NOTE | O8: LINK | P8: ALLENAMENTO | Q8: REPS/TEMPO | R8: RECUPERO | S8: DESCRIZIONE/NOTE | T8: LINK | U8: ALLENAMENTO | V8: REPS/TEMPO | W8: RECUPERO | X8: DESCRIZIONE/NOTE | Y8: LINK
D9: =IF($A9="","",VLOOKUP(A9,'DB ESERCIZI'!$B$2:$K$83,9,FALSE)) | E9: =IF($A9="","",HYPERLINK(VLOOKUP(A9,'DB ESERCIZI'!$B$2:$K$83,10,FALSE))) | I9: =IF($A9="","",VLOOKUP(F9,'DB ESERCIZI'!$B$2:$K$83,9,FALSE)) | J9: =IF($A9="","",HYPERLINK(VLOOKUP(F9,'DB ESERCIZI'!$B$2:$K$83,10,FALSE))) | N9: =IF($A9="","",VLOOKUP(K9,'DB ESERCIZI'!$B$2:$K$83,9,FALSE)) | O9: =IF($A9="","",HYPERLINK(VLOOKUP(K9,'DB ESERCIZI'!$B$2:$K$83,10,FALSE))) | S9: =IF($A9="","",VLOOKUP(P9,'DB ESERCIZI'!$B$2:$K$83,9,FALSE)) | T9: =IF($A9="","",HYPERLINK(VLOOKUP(P9,'DB ESERCIZI'!$B$2:$K$83,10,FALSE))) | X9: =IF($A9="","",VLOOKUP(U9,'DB ESERCIZI'!$B$2:$K$83,9,FALSE)) | Y9: =IF($A9="","",HYPERLINK(VLOOKUP(U9,'DB ESERCIZI'!$B$2:$K$83,10,FALSE)))
D10: =IF($A10="","",VLOOKUP(A10,'DB ESERCIZI'!$B$2:$K$83,9,FALSE)) | E10: =IF($A10="","",HYPERLINK(VLOOKUP(A10,'DB ESERCIZI'!$B$2:$K$83,10,FALSE))) | I10: =IF($A10="","",VLOOKUP(F10,'DB ESERCIZI'!$B$2:$K$83,9,FALSE)) | J10: =IF($A10="","",HYPERLINK(VLOOKUP(F10,'DB ESERCIZI'!$B$2:$K$83,10,FALSE))) | N10: =IF($A10="","",VLOOKUP(K10,'DB ESERCIZI'!$B$2:$K$83,9,FALSE)) | O10: =IF($A10="","",HYPERLINK(VLOOKUP(K10,'DB ESERCIZI'!$B$2:$K$83,10,FALSE))) | S10: =IF($A10="","",VLOOKUP(P10,'DB ESERCIZI'!$B$2:$K$83,9,FALSE)) | T10: =IF($A10="","",HYPERLINK(VLOOKUP(P10,'DB ESERCIZI'!$B$2:$K$83,10,FALSE))) | X10: =IF($A10="","",VLOOKUP(U10,'DB ESERCIZI'!$B$2:$K$83,9,FALSE)) | Y10: =IF($A10="","",HYPERLINK(VLOOKUP(U10,'DB ESERCIZI'!$B$2:$K$83,10,FALSE)))
D11: =IF($A11="","",VLOOKUP(A11,'DB ESERCIZI'!$B$2:$K$83,9,FALSE)) | E11: =IF($A11="","",HYPERLINK(VLOOKUP(A11,'DB ESERCIZI'!$B$2:$K$83,10,FALSE))) | I11: =IF($A11="","",VLOOKUP(F11,'DB ESERCIZI'!$B$2:$K$83,9,FALSE)) | J11: =IF($A11="","",HYPERLINK(VLOOKUP(F11,'DB ESERCIZI'!$B$2:$K$83,10,FALSE))) | N11: =IF($A11="","",VLOOKUP(K11,'DB ESERCIZI'!$B$2:$K$83,9,FALSE)) | O11: =IF($A11="","",HYPERLINK(VLOOKUP(K11,'DB ESERCIZI'!$B$2:$K$83,10,FALSE))) | S11: =IF($A11="","",VLOOKUP(P11,'DB ESERCIZI'!$B$2:$K$83,9,FALSE)) | T11: =IF($A11="","",HYPERLINK(VLOOKUP(P11,'DB ESERCIZI'!$B$2:$K$83,10,FALSE))) | X11: =IF($A11="","",VLOOKUP(U11,'DB ESERCIZI'!$B$2:$K$83,9,FALSE)) | Y11: =IF($A11="","",HYPERLINK(VLOOKUP(U11,'DB ESERCIZI'!$B$2:$K$83,10,FALSE)))
D12: =IF($A12="","",VLOOKUP(A12,'DB ESERCIZI'!$B$2:$K$83,9,FALSE)) | E12: =IF($A12="","",HYPERLINK(VLOOKUP(A12,'DB ESERCIZI'!$B$2:$K$83,10,FALSE))) | I12: =IF($A12="","",VLOOKUP(F12,'DB ESERCIZI'!$B$2:$K$83,9,FALSE)) | J12: =IF($A12="","",HYPERLINK(VLOOKUP(F12,'DB ESERCIZI'!$B$2:$K$83,10,FALSE))) | N12: =IF($A12="","",VLOOKUP(K12,'DB ESERCIZI'!$B$2:$K$83,9,FALSE)) | O12: =IF($A12="","",HYPERLINK(VLOOKUP(K12,'DB ESERCIZI'!$B$2:$K$83,10,FALSE))) | S12: =IF($A12="","",VLOOKUP(P12,'DB ESERCIZI'!$B$2:$K$83,9,FALSE)) | T12: =IF($A12="","",HYPERLINK(VLOOKUP(P12,'DB ESERCIZI'!$B$2:$K$83,10,FALSE))) | X12: =IF($A12="","",VLOOKUP(U12,'DB ESERCIZI'!$B$2:$K$83,9,FALSE)) | Y12: =IF($A12="","",HYPERLINK(VLOOKUP(U12,'DB ESERCIZI'!$B$2:$K$83,10,FALSE)))
D13: =IF($A13="","",VLOOKUP(A13,'DB ESERCIZI'!$B$2:$K$83,9,FALSE)) | E13: =IF($A13="","",HYPERLINK(VLOOKUP(A13,'DB ESERCIZI'!$B$2:$K$83,10,FALSE))) | I13: =IF($A13="","",VLOOKUP(F13,'DB ESERCIZI'!$B$2:$K$83,9,FALSE)) | J13: =IF($A13="","",HYPERLINK(VLOOKUP(F13,'DB ESERCIZI'!$B$2:$K$83,10,FALSE))) | N13: =IF($A13="","",VLOOKUP(K13,'DB ESERCIZI'!$B$2:$K$83,9,FALSE)) | O13: =IF($A13="","",HYPERLINK(VLOOKUP(K13,'DB ESERCIZI'!$B$2:$K$83,10,FALSE))) | S13: =IF($A13="","",VLOOKUP(P13,'DB ESERCIZI'!$B$2:$K$83,9,FALSE)) | T13: =IF($A13="","",HYPERLINK(VLOOKUP(P13,'DB ESERCIZI'!$B$2:$K$83,10,FALSE))) | X13: =IF($A13="","",VLOOKUP(U13,'DB ESERCIZI'!$B$2:$K$83,9,FALSE)) | Y13: =IF($A13="","",HYPERLINK(VLOOKUP(U13,'DB ESERCIZI'!$B$2:$K$83,10,FALSE)))
D14: =IF($A14="","",VLOOKUP(A14,'DB ESERCIZI'!$B$2:$K$83,9,FALSE)) | E14: =IF($A14="","",HYPERLINK(VLOOKUP(A14,'DB ESERCIZI'!$B$2:$K$83,10,FALSE))) | I14: =IF($A14="","",VLOOKUP(F14,'DB ESERCIZI'!$B$2:$K$83,9,FALSE)) | J14: =IF($A14="","",HYPERLINK(VLOOKUP(F14,'DB ESERCIZI'!$B$2:$K$83,10,FALSE))) | N14: =IF($A14="","",VLOOKUP(K14,'DB ESERCIZI'!$B$2:$K$83,9,FALSE)) | O14: =IF($A14="","",HYPERLINK(VLOOKUP(K14,'DB ESERCIZI'!$B$2:$K$83,10,FALSE))) | S14: =IF($A14="","",VLOOKUP(P14,'DB ESERCIZI'!$B$2:$K$83,9,FALSE)) | T14: =IF($A14="","",HYPERLINK(VLOOKUP(P14,'DB ESERCIZI'!$B$2:$K$83,10,FALSE))) | X14: =IF($A14="","",VLOOKUP(U14,'DB ESERCIZI'!$B$2:$K$83,9,FALSE)) | Y14: =IF($A14="","",HYPERLINK(VLOOKUP(U14,'DB ESERCIZI'!$B$2:$K$83,10,FALSE)))
D15: =IF($A15="","",VLOOKUP(A15,'DB ESERCIZI'!$B$2:$K$83,9,FALSE)) | E15: =IF($A15="","",HYPERLINK(VLOOKUP(A15,'DB ESERCIZI'!$B$2:$K$83,10,FALSE))) | I15: =IF($A15="","",VLOOKUP(F15,'DB ESERCIZI'!$B$2:$K$83,9,FALSE)) | J15: =IF($A15="","",HYPERLINK(VLOOKUP(F15,'DB ESERCIZI'!$B$2:$K$83,10,FALSE))) | N15: =IF($A15="","",VLOOKUP(K15,'DB ESERCIZI'!$B$2:$K$83,9,FALSE)) | O15: =IF($A15="","",HYPERLINK(VLOOKUP(K15,'DB ESERCIZI'!$B$2:$K$83,10,FALSE))) | S15: =IF($A15="","",VLOOKUP(P15,'DB ESERCIZI'!$B$2:$K$83,9,FALSE)) | T15: =IF($A15="","",HYPERLINK(VLOOKUP(P15,'DB ESERCIZI'!$B$2:$K$83,10,FALSE))) | X15: =IF($A15="","",VLOOKUP(U15,'DB ESERCIZI'!$B$2:$K$83,9,FALSE)) | Y15: =IF($A15="","",HYPERLINK(VLOOKUP(U15,'DB ESERCIZI'!$B$2:$K$83,10,FALSE)))
D16: =IF($A16="","",VLOOKUP(A16,'DB ESERCIZI'!$B$2:$K$83,9,FALSE)) | E16: =IF($A16="","",HYPERLINK(VLOOKUP(A16,'DB ESERCIZI'!$B$2:$K$83,10,FALSE))) | I16: =IF($A16="","",VLOOKUP(F16,'DB ESERCIZI'!$B$2:$K$83,9,FALSE)) | J16: =IF($A16="","",HYPERLINK(VLOOKUP(F16,'DB ESERCIZI'!$B$2:$K$83,10,FALSE))) | N16: =IF($A16="","",VLOOKUP(K16,'DB ESERCIZI'!$B$2:$K$83,9,FALSE)) | O16: =IF($A16="","",HYPERLINK(VLOOKUP(K16,'DB ESERCIZI'!$B$2:$K$83,10,FALSE))) | S16: =IF($A16="","",VLOOKUP(P16,'DB ESERCIZI'!$B$2:$K$83,9,FALSE)) | T16: =IF($A16="","",HYPERLINK(VLOOKUP(P16,'DB ESERCIZI'!$B$2:$K$83,10,FALSE))) | X16: =IF($A16="","",VLOOKUP(U16,'DB ESERCIZI'!$B$2:$K$83,9,FALSE)) | Y16: =IF($A16="","",HYPERLINK(VLOOKUP(U16,'DB ESERCIZI'!$B$2:$K$83,10,FALSE)))
D17: =IF($A17="","",VLOOKUP(A17,'DB ESERCIZI'!$B$2:$K$83,9,FALSE)) | E17: =IF($A17="","",HYPERLINK(VLOOKUP(A17,'DB ESERCIZI'!$B$2:$K$83,10,FALSE))) | I17: =IF($A17="","",VLOOKUP(F17,'DB ESERCIZI'!$B$2:$K$83,9,FALSE)) | J17: =IF($A17="","",HYPERLINK(VLOOKUP(F17,'DB ESERCIZI'!$B$2:$K$83,10,FALSE))) | N17: =IF($A17="","",VLOOKUP(K17,'DB ESERCIZI'!$B$2:$K$83,9,FALSE)) | O17: =IF($A17="","",HYPERLINK(VLOOKUP(K17,'DB ESERCIZI'!$B$2:$K$83,10,FALSE))) | S17: =IF($A17="","",VLOOKUP(P17,'DB ESERCIZI'!$B$2:$K$83,9,FALSE)) | T17: =IF($A17="","",HYPERLINK(VLOOKUP(P17,'DB ESERCIZI'!$B$2:$K$83,10,FALSE))) | X17: =IF($A17="","",VLOOKUP(U17,'DB ESERCIZI'!$B$2:$K$83,9,FALSE)) | Y17: =IF($A17="","",HYPERLINK(VLOOKUP(U17,'DB ESERCIZI'!$B$2:$K$83,10,FALSE)))
D18: =IF($A18="","",VLOOKUP(A18,'DB ESERCIZI'!$B$2:$K$83,9,FALSE)) | E18: =IF($A18="","",HYPERLINK(VLOOKUP(A18,'DB ESERCIZI'!$B$2:$K$83,10,FALSE))) | I18: =IF($A18="","",VLOOKUP(F18,'DB ESERCIZI'!$B$2:$K$83,9,FALSE)) | J18: =IF($A18="","",HYPERLINK(VLOOKUP(F18,'DB ESERCIZI'!$B$2:$K$83,10,FALSE))) | N18: =IF($A18="","",VLOOKUP(K18,'DB ESERCIZI'!$B$2:$K$83,9,FALSE)) | O18: =IF($A18="","",HYPERLINK(VLOOKUP(K18,'DB ESERCIZI'!$B$2:$K$83,10,FALSE))) | S18: =IF($A18="","",VLOOKUP(P18,'DB ESERCIZI'!$B$2:$K$83,9,FALSE)) | T18: =IF($A18="","",HYPERLINK(VLOOKUP(P18,'DB ESERCIZI'!$B$2:$K$83,10,FALSE))) | X18: =IF($A18="","",VLOOKUP(U18,'DB ESERCIZI'!$B$2:$K$83,9,FALSE)) | Y18: =IF($A18="","",HYPERLINK(VLOOKUP(U18,'DB ESERCIZI'!$B$2:$K$83,10,FALSE)))
D19: =IF($A19="","",VLOOKUP(A19,'DB ESERCIZI'!$B$2:$K$83,9,FALSE)) | E19: =IF($A19="","",HYPERLINK(VLOOKUP(A19,'DB ESERCIZI'!$B$2:$K$83,10,FALSE))) | I19: =IF($A19="","",VLOOKUP(F19,'DB ESERCIZI'!$B$2:$K$83,9,FALSE)) | J19: =IF($A19="","",HYPERLINK(VLOOKUP(F19,'DB ESERCIZI'!$B$2:$K$83,10,FALSE))) | N19: =IF($A19="","",VLOOKUP(K19,'DB ESERCIZI'!$B$2:$K$83,9,FALSE)) | O19: =IF($A19="","",HYPERLINK(VLOOKUP(K19,'DB ESERCIZI'!$B$2:$K$83,10,FALSE))) | S19: =IF($A19="","",VLOOKUP(P19,'DB ESERCIZI'!$B$2:$K$83,9,FALSE)) | T19: =IF($A19="","",HYPERLINK(VLOOKUP(P19,'DB ESERCIZI'!$B$2:$K$83,10,FALSE))) | X19: =IF($A19="","",VLOOKUP(U19,'DB ESERCIZI'!$B$2:$K$83,9,FALSE)) | Y19: =IF($A19="","",HYPERLINK(VLOOKUP(U19,'DB ESERCIZI'!$B$2:$K$83,10,FALSE)))
D20: =IF($A20="","",VLOOKUP(A20,'DB ESERCIZI'!$B$2:$K$83,9,FALSE)) | E20: =IF($A20="","",HYPERLINK(VLOOKUP(A20,'DB ESERCIZI'!$B$2:$K$83,10,FALSE))) | I20: =IF($A20="","",VLOOKUP(F20,'DB ESERCIZI'!$B$2:$K$83,9,FALSE)) | J20: =IF($A20="","",HYPERLINK(VLOOKUP(F20,'DB ESERCIZI'!$B$2:$K$83,10,FALSE))) | N20: =IF($A20="","",VLOOKUP(K20,'DB ESERCIZI'!$B$2:$K$83,9,FALSE)) | O20: =IF($A20="","",HYPERLINK(VLOOKUP(K20,'DB ESERCIZI'!$B$2:$K$83,10,FALSE))) | S20: =IF($A20="","",VLOOKUP(P20,'DB ESERCIZI'!$B$2:$K$83,9,FALSE)) | T20: =IF($A20="","",HYPERLINK(VLOOKUP(P20,'DB ESERCIZI'!$B$2:$K$83,10,FALSE))) | X20: =IF($A20="","",VLOOKUP(U20,'DB ESERCIZI'!$B$2:$K$83,9,FALSE)) | Y20: =IF($A20="","",HYPERLINK(VLOOKUP(U20,'DB ESERCIZI'!$B$2:$K$83,10,FALSE)))
... D65: =IF($A65="","",VLOOKUP(A65,'DB ESERCIZI'!$B$2:$K$83,9,FALSE)) | E65: =IF($A65="","",HYPERLINK(VLOOKUP(A65,'DB ESERCIZI'!$B$2:$K$83,10,FALSE))) | I65: =IF($A65="","",VLOOKUP(F65,'DB ESERCIZI'!$B$2:$K$83,9,FALSE)) | J65: =IF($A65="","",HYPERLINK(VLOOKUP(F65,'DB ESERCIZI'!$B$2:$K$83,10,FALSE))) | N65: =IF($A65="","",VLOOKUP(K65,'DB ESERCIZI'!$B$2:$K$83,9,FALSE)) | O65: =IF($A65="","",HYPERLINK(VLOOKUP(K65,'DB ESERCIZI'!$B$2:$K$83,10,FALSE))) | S65: =IF($A65="","",VLOOKUP(P65,'DB ESERCIZI'!$B$2:$K$83,9,FALSE)) | T65: =IF($A65="","",HYPERLINK(VLOOKUP(P65,'DB ESERCIZI'!$B$2:$K$83,10,FALSE))) | X65: =IF($A65="","",VLOOKUP(U65,'DB ESERCIZI'!$B$2:$K$83,9,FALSE)) | Y65: =IF($A65="","",HYPERLINK(VLOOKUP(U65,'DB ESERCIZI'!$B$2:$K$83,10,FALSE)))

Sheet TEST
B1: TEST | D1: RISULTATO | G1: LIVELLO | L1: NOTE/COMMENTI
B2: RESISTENZA | D2: TEMPO (SEC) | E2: LIVELLO | G2: PRO | H2: AVANZATO | I2: INTERMEDIO | J2: BASE | L2: NOTE
B3: 1km | D3: 225 | E3: =(360-D3)/1.8 -> 75 | G3: < 3'30'' | H3: <3'50'' | I3: <4'10'' | J3: >4'
B4: 3km | D4: 720 | E4: =(300-D4/3)/0.8 -> 75 | G4: <11'45'' | H4: <12'30'' | I4: <13'45'' | J4: >13'45''
B6: CAPAC. ANAEROBICA | D6: NUM. | E6: LIVELLO | G6: PRO | H6: AVANZATO | I6: INTERMEDIO | J6: BASE | L6: NOTE
B7: Navetta 10mt x 30" | D7: 14 | E7: =(D7-4)*10 -> 100 | G7: >12 | H7: >10 | I7: >7 | J7: <6 | L7: imposta il timer sul tuo telefono a 30" e cerca di fare più navette possibili nel tempo
B8: 20'' Ankle Jump Test | D8: 11 | E8: =(D8-2)*10 -> 90 | G8: >10 | H8: 9 | I8: >7 | J8: <6
B9: 20'' SL Ankle Jump Test (DX) | D9: 8 | E9: =(D9-1)*10 -> 70 | G9: >9 | H9: 8 | I9: >6 | J9: <5
B10: 20'' SL Ankle Jump Test (SX) | D10: 7 | E10: =(D10-1)*10 -> 60 | G10: >9 | H10: 8 | I10: >6 | J10: <5
B12: FORZA PB | D12: TEMPO (SEC) | E12: LIVELLO | G12: PRO | H12: AVANZATO | I12: INTERMEDIO | J12: BASE | L12: NOTE
B13: Wall Sit Iso | D13: 187 | E13: =(D13)/1.8 -> 103.88889 | G13: >180" | H13: >120" | I13: >90" | J13: <80"
B14: SL Wall Sit Iso DX | D14: 65 | E14: =(D14)*1.2 -> 78 | G14: >90" | H14: >60" | I14: >40" | J14: <40"
B15: SL Wall Sit Iso SX | D15: 68 | E15: =(D15)*1.2 -> 81.6 | G15: >90" | H15: >60" | I15: >40" | J15: <40"
B16: Affondo Iso DX | D16: 150 | E16: =(D16)/1.8 -> 83.333333 | G16: >180" | H16: >120" | I16: >90" | J16: <80" | L16: per la distanza tra I 2 piedi: posizionati come se dovessi fare dei piegamenti, solleva il piede con cui devi fare il test e posizionalo circa ad altezza del petto/spalle, alzati e vai in posizione di affondo con la gamba posteriore più tesa possibile
B17: Affondo Iso SX | D17: 140 | E17: =(D17)/1.8 -> 77.777778 | G17: >180" | H17: >120" | I17: >90" | J17: <80"
B19: FORZA PA | D19: NUM. | E19: LIVELLO | G19: PRO | H19: AVANZATO | I19: INTERMEDIO | J19: BASE | L19: NOTE
B20: Push ups | D20: 48 | E20: =(D20)/0.5 -> 96 | G20: >40 | H20: >30 | I20: >20 | J20: <15 | L20: Esegui dei piegamenti completi toccando il petto a terra e distendendo le braccia
B21: pull ups | D21: 12 | E21: =(D21)/0.16 -> 75 | G21: >12 | H21: >8 | I21: >4 | J21: <2
B22: plank frontale | D22: 200 | E22: =(D22)/2.4 -> 83.333333 | G22: >120" | H22: >60" | I22: >40" | J22: <30"
B24: VELOCITA' | D24: TEMPO (SEC) | E24: LIVELLO | G24: PRO | H24: AVANZATO | I24: INTERMEDIO | J24: BASE | L24: NOTE
B25: 50mt | D25: 7.5 | E25: =(24-D25*2.2)*10 -> 75 | G25: <7" | H25: <8" | I25: <9" | J25: >10"
B26: T Sprint (10mt) | D26: 10 | E26: =(320-D26*20)/1.4 -> 85.714286 | G26: <10" | H26: <12" | I26: <14" | J26: >14"
B28: FORZA ESPLOSIVA | D28: CM | E28: LIVELLO | G28: PRO | H28: AVANZATO | I28: INTERMEDIO | J28: BASE | L28: NOTE
B29: Broad Jump | D29: 260 | E29: =(D29)/2.9 -> 89.655172 | G29: >250cm | H29: >200cm | I29: >170cm | J29: <160cm
B30: SL Broad Jump DX | D30: 240 | E30: =(D30)/2.8 -> 85.714286 | G30: >240cm | H30: >190cm | I30: >150cm | J30: <140cm
B31: SL Broad Jump SX | D31: 230 | E31: =(D31)/2.8 -> 82.142857 | G31: >240cm | H31: >190cm | I31: >150cm | J31: <140cm
B33: FASCIA | D33: SENSAZIONI | E33: LIVELLO | G33: PRO | H33: AVANZATO | I33: INTERMEDIO | J33: BASE | L33: NOTE
B34: 120'' Pogo Jumps | D34: senti fatica ai glutei/ addome | E34: =IF(D34=G34,100,IF(D34=H34,75,IF(D34=I34,50,30))) -> 100 | G34: senti fatica ai glutei/ addome | H34: senti fatica su flessori/coscia | I34: senti fatica su quadricipiti/ polpacci | J34: senti fatica su caviglia/ piede | L34: imposta timer 2 minuti ed esegui dei saltelli sul posto alla frequenza di circa 2 saltelli al secondo, concentrati sul mantenere il punto di contatto sempre nell'avampiede (no tallone) e caviglia rigida
B35: 180" toe curls SX | D35: senti fatica su flessori/coscia | E35: =IF(D35=G35,100,IF(D35=H35,75,IF(D35=I35,50,30))) -> 75 | G35: senti fatica ai glutei/ addome | H35: senti fatica su flessori/coscia | I35: senti fatica su quadricipiti/ polpacci | J35: senti fatica su caviglia/ piede | L35: esegui per 3 minuti (per piede) l'esercizio "Toe curls", posizionandoti in piedi con 1 piede avanti, appoggiando l'avampiede su un asciugamano ed eseguendo delle "retrazioni" delle dita, come se dovessi spingere sull'asciugamano e "accorciare" la tua pianta del piede. mantieni circa il 70/80% del peso sulla gamba avanti (link video: xxxx)
B36: 180" toe curls DX | D36: senti fatica ai glutei/ addome | E36: =IF(D36=G36,100,IF(D36=H36,75,IF(D36=I36,50,30))) -> 100 | G36: senti fatica ai glutei/ addome | H36: senti fatica su flessori/coscia | I36: senti fatica su quadricipiti/ polpacci | J36: senti fatica su caviglia/ piede | L36: esegui per 3 minuti (per piede) l'esercizio "Toe curls", posizionandoti in piedi con 1 piede avanti, appoggiando l'avampiede su un asciugamano ed eseguendo delle "retrazioni" delle dita, come se dovessi spingere sull'asciugamano e "accorciare" la tua pianta del piede. mantieni circa il 70/80% del peso sulla gamba avanti (link video: xxxx)
B38: TECNICA | D38: N. MAX | E38: LIVELLO | G38: PRO | H38: AVANZATO | I38: INTERMEDIO | J38: BASE | L38: NOTE
B39: Palleggi Piede forte | D39: 160 | E39: =(D39)/1.8 -> 88.888889 | G39: >150 | H39: >100 | I39: >50 | J39: <50 | L39: consecutivi senza far cadere la palla, max. 3 tentativi
B40: Palleggi piede debole | D40: 140 | E40: =(D40)/1.5 -> 93.333333 | G40: >120 | H40: >80 | I40: >30 | J40: <30 | L40: consecutivi senza far cadere la palla, max. 3 tentativi
B41: Palleggi Testa | D41: 85 | E41: =(D41)/1 -> 85 | G41: >100 | H41: >50 | I41: >25 | J41: <25 | L41: consecutivi senza far cadere la palla, max. 3 tentativi
B42: Piramide Palleggi | D42: 9 | E42: =D42*10 -> 90 | G42: >10 | H42: >5 | I42: >3 | J42: <2 | L42: consecutivi senza far cadere la palla, max. 3 tentativi (piede coscia testa coscia piede)
B43: 10 tiri traversa (da fuori area) piede forte | D43: 4 | E43: =D43*22 -> 88 | G43: >4 | H43: 3 | I43: 2 | J43: 1/0 | L43: max 3 tentativi
B44: 10 tiri traversa (da fuori area) piede debole | D44: 4 | E44: =D44*22 -> 88 | G44: >4 | H44: 3 | I44: 2 | J44: 1/0 | L44: max 3 tentativi
B45: 10 passaggi palo (da fuori area) piede forte | D45: 3 | E45: =D45*22 -> 66 | G45: >4 | H45: 3 | I45: 2 | J45: 1/0 | L45: max 3 tentativi
B46: 10 passaggi palo (da fuori area) piede debole | D46: 3 | E46: =D46*22 -> 66 | G46: >4 | H46: 3 | I46: 2 | J46: 1/0 | L46: max 3 tentativi

Sheet CALCOLO MASSIMALI
B1: inserisci qui quante ripetizioni hai fatto | C1: inserisci qui il peso che hai usato | D1: QUESTO SARA' IL CALCOLO DELLA PERCENTUALE DEL TUO PESO MASSIMALE (NON TOCCARE I CAMPI QUI SOTTO)
A2: ESERCIZIO | B2: RIPETIZIONI | C2: PESO (kg) | D2: 40% | E2: 50% | F2: 60% | G2: 70% | H2: 80% | I2: 85% | J2: 90% | K2: 100%
A3: SQUAT | B3: 6 | C3: 90 | D3: =$K3*D$2 -> 41.811847 | E3: =$K3*E$2 -> 52.264808 | F3: =$K3*F$2 -> 62.71777 | G3: =$K3*G$2 -> 73.170732 | H3: =$K3*H$2 -> 83.623693 | I3: =$K3*I$2 -> 88.850174 | J3: =$K3*J$2 -> 94.076655 | K3: =C3/(1.0278-(0.0278*B3)) -> 104.52962
A4: DEADLIFT | B4: 10 | C4: 80 | D4: =$K4*D$2 -> 42.678047 | E4: =$K4*E$2 -> 53.347559 | F4: =$K4*F$2 -> 64.017071 | G4: =$K4*G$2 -> 74.686583 | H4: =$K4*H$2 -> 85.356095 | I4: =$K4*I$2 -> 90.690851 | J4: =$K4*J$2 -> 96.025607 | K4: =C4/(1.0278-(0.0278*B4)) -> 106.69512
A5: HIP TRUST | D5: =$K5*D$2 -> 0 | E5: =$K5*E$2 -> 0 | F5: =$K5*F$2 -> 0 | G5: =$K5*G$2 -> 0 | H5: =$K5*H$2 -> 0 | I5: =$K5*I$2 -> 0 | J5: =$K5*J$2 -> 0 | K5: =C5/(1.0278-(0.0278*B5)) -> 0
A6: BULGARIAN SQUAT | D6: =$K6*D$2 -> 0 | E6: =$K6*E$2 -> 0 | F6: =$K6*F$2 -> 0 | G6: =$K6*G$2 -> 0 | H6: =$K6*H$2 -> 0 | I6: =$K6*I$2 -> 0 | J6: =$K6*J$2 -> 0 | K6: =C6/(1.0278-(0.0278*B6)) -> 0
A7: PANCA PIANA | D7: =$K7*D$2 -> 0 | E7: =$K7*E$2 -> 0 | F7: =$K7*F$2 -> 0 | G7: =$K7*G$2 -> 0 | H7: =$K7*H$2 -> 0 | I7: =$K7*I$2 -> 0 | J7: =$K7*J$2 -> 0 | K7: =C7/(1.0278-(0.0278*B7)) -> 0
A8: SHOULDER PRESS | D8: =$K8*D$2 -> 0 | E8: =$K8*E$2 -> 0 | F8: =$K8*F$2 -> 0 | G8: =$K8*G$2 -> 0 | H8: =$K8*H$2 -> 0 | I8: =$K8*I$2 -> 0 | J8: =$K8*J$2 -> 0 | K8: =C8/(1.0278-(0.0278*B8)) -> 0
A9: PULL UPS | D9: =$K9*D$2 -> 0 | E9: =$K9*E$2 -> 0 | F9: =$K9*F$2 -> 0 | G9: =$K9*G$2 -> 0 | H9: =$K9*H$2 -> 0 | I9: =$K9*I$2 -> 0 | J9: =$K9*J$2 -> 0 | K9: =C9/(1.0278-(0.0278*B9)) -> 0

Sheet DB ESERCIZI
A1: Index | B1: Nome | C1: Categoria | D1: Obiettivo | E1: Area | F1: Corpo Libero | G1: Peso | H1: Difficoltà | I1: Focus | J1: Descrizione | K1: Link
A2: 1 | B2: Towel Curls | C2: Fascia | E2: Parte Bassa | F2: SI | H2: 1 | J2: esegui una retrazione del piede utilizzando un asciugamano | K2: https://youtube.com/shorts/qW8YXLmdke0
A3: 2 | B3: Toes Up Down | C3: Fascia | E3: Parte Bassa | F3: SI | H3: 1 | K3: https://youtube.com/shorts/1_TtKlvDeqk?feature=share
A4: 3 | B4: Toes Up Down 2 | C4: Fascia | E4: Parte Bassa | F4: SI | H4: 1 | K4: https://youtube.com/shorts/JctaRd1xxng
A5: 4 | B5: Toe Bounces | C5: Fascia | E5: Parte Bassa | F5: SI | H5: 2 | K5: https://youtube.com/shorts/rleHrcL6teA?feature=share
A6: 5 | B6: FY Towe SLRDL | C6: Fascia | E6: Parte Bassa | F6: SI | H6: 2 | K6: https://youtube.com/shorts/_0TsEKkUqGw?feature=share
A7: 6 | B7: FY Towel 8 | C7: Fascia | E7: Parte Bassa | F7: SI | H7: 2 | K7: https://youtube.com/shorts/V805vZi3rLs?feature=share
A8: 7 | B8: SL Toe Bounces | C8: Fascia | E8: Parte Bassa | F8: SI | H8: 3 | K8: https://youtube.com/shorts/V5SVWUH1_50?feature=share
A9: 8 | B9: Iso Runner | C9: Fascia | E9: Parte Bassa | F9: SI | H9: 3 | K9: https://youtube.com/shorts/nvENLHoWSR4?feature=share
A10: 9 | B10: Fascia Single leg runner (towel) | C10: Fascia | E10: Parte Bassa | F10: SI | H10: 3 | K10: https://youtube.com/shorts/_0TsEKkUqGw?feature=share
A11: 10 | B11: tibialis raise | C11: Forza | E11: Parte Bassa | F11: SI | K11: https://youtube.com/shorts/P4H0NE-HCsE?feature=share
A12: 11 | B12: calf raises | C12: Forza | E12: Parte Bassa | G12: SI | K12: https://youtube.com/shorts/De9Dl-RHKD0?feature=share
A13: 12 | B13: patrick step up | C13: Forza | E13: Parte Bassa | G13: SI | K13: https://youtube.com/shorts/RDCTvQKcmv0?feature=share
A14: 13 | B14: poliquin step up | C14: Forza | E14: Parte Bassa | F14: SI | K14: https://youtube.com/shorts/2ABf__3KZP4?feature=share
A15: 14 | B15: atg split squat | C15: Forza | E15: Parte Bassa | K15: https://youtube.com/shorts/a0iGmxKW4_0?feature=share
A16: 15 | B16: reverse nordic | C16: Forza | E16: Parte Bassa | K16: https://youtube.com/shorts/VMULf9rZ4TE?feature=share
A17: 16 | B17: stacco rumeno | C17: Forza | E17: Parte Bassa | K17: https://youtube.com/shorts/Xr7iEK_5HNQ?feature=share
A18: 17 | B18: hip thrust | C18: Forza | E18: Parte Bassa | K18: https://youtube.com/shorts/C6Y0yEh4Ed4?feature=share
A19: 18 | B19: squat | C19: Forza | E19: Parte Bassa
A20: 19 | B20: squat bulgaro | C20: Forza | E20: Parte Bassa | K20: https://youtube.com/shorts/9_fCiuYPd1o?feature=share
A21: 20 | B21: Affondi in camminata | C21: Forza | E21: Parte Bassa | K21: https://youtube.com/shorts/kAnLd3sRhmA?feature=share
A22: 21 | B22: Affondi sul posto | C22: Forza | E22: Parte Bassa | K22: https://youtube.com/shorts/ruFaw3pDMGQ?feature=share
A23: 22 | B23: copenaghen plank | C23: Forza | E23: Parte Bassa | K23: https://youtube.com/shorts/9pLQwT8RuUc?feature=share
A24: 23 | B24: Glute bridge ad una gamba | C24: Forza | E24: Parte Bassa | K24: https://youtube.com/shorts/FQPEqDy8IBI?feature=share
A25: 24 | B25: Affondo isometrico | C25: Forza | E25: Parte Bassa | K25: https://youtube.com/shorts/nvENLHoWSR4?feature=share
A26: 25 | B26: Wall sit | C26: Forza | E26: Core | K26: https://youtube.com/shorts/EuGsglumupM?feature=share
A27: 26 | B27: nordic | C27: Forza | E27: Core | K27: https://youtube.com/shorts/Wx_d0y8iGxM?feature=share
A28: 27 | B28: front squat | C28: Forza | E28: Parte Bassa | K28: https://youtube.com/shorts/2-fkHNhdW4I?feature=share
A29: 28 | B29: sumo deadlift | C29: Forza | E29: Parte Bassa | K29: stefano
A30: 29 | B30: Kettlebell swing | C30: Forza | D30: Forza Esplosiva | E30: Full Body | K30: https://youtube.com/shorts/E87gS0QjGOw?feature=share
A31: 30 | B31: single leg rdl | C31: Forza | E31: Parte Bassa | K31: https://youtube.com/shorts/Do1KR00uAqc?feature=share
A32: 31 | B32: sissy squat | C32: Forza | D32: Prevenzione | E32: Parte Bassa | K32: stefano
A33: 32 | B33: knee extension | C33: Forza | D33: Prevenzione | E33: Parte Bassa | K33: stefano
A34: 33 | B34: Nordic hamstring | C34: Forza | K34: stefano
A35: 34 | B35: ATG Lunge | K35: https://youtube.com/shorts/WGePf1hZ7_I?feature=share
A36: 35 | B36: Affondo isometrico con tallone sollevato | K36: https://youtube.com/shorts/nvENLHoWSR4?feature=share
A37: 36 | B37: Squat Jump
A38: 37 | B38: Skater Jump | K38: https://youtube.com/shorts/jIdbGisRMV4?feature=share
A39: 38 | B39: Pogo Jumps | K39: https://youtube.com/shorts/rleHrcL6teA?feature=share
A40: 39 | B40: Single Leg Pogo Jumps | K40: https://youtube.com/shorts/V5SVWUH1_50?feature=share
...
